============================= test session starts ==============================
platform linux -- Python 3.9.18, pytest-7.4.3, pluggy-1.3.0
django: version: 3.2.23, settings: saleor.tests.settings (from option)
rootdir: /home/user/saleor
configfile: setup.cfg
testpaths: saleor
plugins: socket-0.6.0, celery-0.0.0, recording-0.13.1, anyio-4.1.0, asyncio-0.21.1, django-4.7.0, xdist-3.5.0, Faker-20.1.0, cov-4.1.0, mock-3.12.0, django-queries-1.2.0, memray-1.5.0
asyncio: mode=auto
created: 6/6 workers
6 workers [143 items]

........................................................................ [ 50%]
.......................................................................  [100%]
=============================== warnings summary ===============================
saleor/settings.py:219
saleor/settings.py:219
saleor/settings.py:219
saleor/settings.py:219
saleor/settings.py:219
saleor/settings.py:219
saleor/settings.py:219
  /home/user/saleor/saleor/settings.py:219: UserWarning: SECRET_KEY not configured, using a random temporary key.
    warnings.warn("SECRET_KEY not configured, using a random temporary key.")

-- Docs: https://docs.pytest.org/en/stable/how-to/capture-warnings.html
================= 143 passed, 7 warnings in 164.10s (0:02:44) ==================
